=========================================================
Job submitted date = Wed Sep 4 10:31:49 BST 2019
1 nodes ( processes per node )
1 hosts used: comp18
Job output begins
-----------------

../../foreground_functions.py:486: RuntimeWarning: divide by zero encountered in true_divide
  data_cls = data * (2*pi)/(ells*(ells+1))
../../foreground_functions.py:486: RuntimeWarning: divide by zero encountered in true_divide
  data_cls = data * (2*pi)/(ells*(ells+1))
Traceback (most recent call last):
  File "MCMC.py", line 63, in <module>
    sampler = emcee.EnsembleSampler(nwalkers, ndim, log_probability, args=(ells, freqs, data), store=True, backend=backend)
TypeError: __init__() got an unexpected keyword argument 'store'
Traceback (most recent call last):
  File "/mnt/zfsusers/acwgough/.local/lib/python3.6/site-packages/h5py/_hl/files.py", line 182, in make_fid
    fid = h5f.open(name, h5f.ACC_RDWR, fapl=fapl)
  File "h5py/_objects.pyx", line 54, in h5py._objects.with_phil.wrapper
  File "h5py/_objects.pyx", line 55, in h5py._objects.with_phil.wrapper
  File "h5py/h5f.pyx", line 85, in h5py.h5f.open
OSError: Unable to open file (unable to open file: name = '/mnt/zfsusers/acwgough/foreground_moments/mcmc/mcmc_chains/test_chain2.h5', errno = 2, error message = 'No such file or directory', flags = 1, o_flags = 2)

During handling of the above exception, another exception occurred:

Traceback (most recent call last):
  File "MCMC.py", line 57, in <module>
    backend.reset(nwalkers, ndim)
  File "/mnt/zfsusers/acwgough/.local/lib/python3.6/site-packages/emcee-3.0rc2-py3.6.egg/emcee/backends/hdf.py", line 68, in reset
  File "/mnt/zfsusers/acwgough/.local/lib/python3.6/site-packages/emcee-3.0rc2-py3.6.egg/emcee/backends/hdf.py", line 58, in open
  File "/mnt/zfsusers/acwgough/.local/lib/python3.6/site-packages/h5py/_hl/files.py", line 394, in __init__
    swmr=swmr)
  File "/mnt/zfsusers/acwgough/.local/lib/python3.6/site-packages/h5py/_hl/files.py", line 184, in make_fid
    fid = h5f.create(name, h5f.ACC_EXCL, fapl=fapl, fcpl=fcpl)
  File "h5py/_objects.pyx", line 54, in h5py._objects.with_phil.wrapper
  File "h5py/_objects.pyx", line 55, in h5py._objects.with_phil.wrapper
  File "h5py/h5f.pyx", line 105, in h5py.h5f.create
OSError: Unable to create file (unable to open file: name = '/mnt/zfsusers/acwgough/foreground_moments/mcmc/mcmc_chains/test_chain2.h5', errno = 17, error message = 'File exists', flags = 15, o_flags = c2)
srun: error: comp18: tasks 1,3: Exited with exit code 1
../../foreground_functions.py:486: RuntimeWarning: divide by zero encountered in true_divide
  data_cls = data * (2*pi)/(ells*(ells+1))
../../foreground_functions.py:486: RuntimeWarning: divide by zero encountered in true_divide
  data_cls = data * (2*pi)/(ells*(ells+1))
Traceback (most recent call last):
  File "MCMC.py", line 63, in <module>
    sampler = emcee.EnsembleSampler(nwalkers, ndim, log_probability, args=(ells, freqs, data), store=True, backend=backend)
TypeError: __init__() got an unexpected keyword argument 'store'
Traceback (most recent call last):
  File "MCMC.py", line 63, in <module>
    sampler = emcee.EnsembleSampler(nwalkers, ndim, log_probability, args=(ells, freqs, data), store=True, backend=backend)
TypeError: __init__() got an unexpected keyword argument 'store'
../../foreground_functions.py:486: RuntimeWarning: divide by zero encountered in true_divide
  data_cls = data * (2*pi)/(ells*(ells+1))
../../foreground_functions.py:486: RuntimeWarning: divide by zero encountered in true_divide
  data_cls = data * (2*pi)/(ells*(ells+1))
../../foreground_functions.py:486: RuntimeWarning: divide by zero encountered in true_divide
  data_cls = data * (2*pi)/(ells*(ells+1))
../../foreground_functions.py:486: RuntimeWarning: divide by zero encountered in true_divide
  data_cls = data * (2*pi)/(ells*(ells+1))
Traceback (most recent call last):
  File "/mnt/zfsusers/acwgough/.local/lib/python3.6/site-packages/h5py/_hl/files.py", line 182, in make_fid
    fid = h5f.open(name, h5f.ACC_RDWR, fapl=fapl)
  File "h5py/_objects.pyx", line 54, in h5py._objects.with_phil.wrapper
  File "h5py/_objects.pyx", line 55, in h5py._objects.with_phil.wrapper
  File "h5py/h5f.pyx", line 85, in h5py.h5f.open
OSError: Unable to open file (unable to lock file, errno = 11, error message = 'Resource temporarily unavailable')

During handling of the above exception, another exception occurred:

Traceback (most recent call last):
  File "MCMC.py", line 57, in <module>
    backend.reset(nwalkers, ndim)
  File "/mnt/zfsusers/acwgough/.local/lib/python3.6/site-packages/emcee-3.0rc2-py3.6.egg/emcee/backends/hdf.py", line 68, in reset
  File "/mnt/zfsusers/acwgough/.local/lib/python3.6/site-packages/emcee-3.0rc2-py3.6.egg/emcee/backends/hdf.py", line 58, in open
  File "/mnt/zfsusers/acwgough/.local/lib/python3.6/site-packages/h5py/_hl/files.py", line 394, in __init__
    swmr=swmr)
  File "/mnt/zfsusers/acwgough/.local/lib/python3.6/site-packages/h5py/_hl/files.py", line 184, in make_fid
    fid = h5f.create(name, h5f.ACC_EXCL, fapl=fapl, fcpl=fcpl)
  File "h5py/_objects.pyx", line 54, in h5py._objects.with_phil.wrapper
  File "h5py/_objects.pyx", line 55, in h5py._objects.with_phil.wrapper
  File "h5py/h5f.pyx", line 105, in h5py.h5f.create
OSError: Unable to create file (unable to open file: name = '/mnt/zfsusers/acwgough/foreground_moments/mcmc/mcmc_chains/test_chain2.h5', errno = 17, error message = 'File exists', flags = 15, o_flags = c2)
Traceback (most recent call last):
  File "MCMC.py", line 63, in <module>
    sampler = emcee.EnsembleSampler(nwalkers, ndim, log_probability, args=(ells, freqs, data), store=True, backend=backend)
TypeError: __init__() got an unexpected keyword argument 'store'
srun: error: comp18: tasks 4,6: Exited with exit code 1
Traceback (most recent call last):
  File "/mnt/zfsusers/acwgough/.local/lib/python3.6/site-packages/h5py/_hl/files.py", line 182, in make_fid
    fid = h5f.open(name, h5f.ACC_RDWR, fapl=fapl)
  File "h5py/_objects.pyx", line 54, in h5py._objects.with_phil.wrapper
  File "h5py/_objects.pyx", line 55, in h5py._objects.with_phil.wrapper
  File "h5py/h5f.pyx", line 85, in h5py.h5f.open
OSError: Unable to open file (unable to lock file, errno = 11, error message = 'Resource temporarily unavailable')

During handling of the above exception, another exception occurred:

Traceback (most recent call last):
  File "MCMC.py", line 57, in <module>
    backend.reset(nwalkers, ndim)
  File "/mnt/zfsusers/acwgough/.local/lib/python3.6/site-packages/emcee-3.0rc2-py3.6.egg/emcee/backends/hdf.py", line 68, in reset
  File "/mnt/zfsusers/acwgough/.local/lib/python3.6/site-packages/emcee-3.0rc2-py3.6.egg/emcee/backends/hdf.py", line 58, in open
  File "/mnt/zfsusers/acwgough/.local/lib/python3.6/site-packages/h5py/_hl/files.py", line 394, in __init__
    swmr=swmr)
  File "/mnt/zfsusers/acwgough/.local/lib/python3.6/site-packages/h5py/_hl/files.py", line 184, in make_fid
    fid = h5f.create(name, h5f.ACC_EXCL, fapl=fapl, fcpl=fcpl)
  File "h5py/_objects.pyx", line 54, in h5py._objects.with_phil.wrapper
  File "h5py/_objects.pyx", line 55, in h5py._objects.with_phil.wrapper
  File "h5py/h5f.pyx", line 105, in h5py.h5f.create
OSError: Unable to create file (unable to open file: name = '/mnt/zfsusers/acwgough/foreground_moments/mcmc/mcmc_chains/test_chain2.h5', errno = 17, error message = 'File exists', flags = 15, o_flags = c2)
Traceback (most recent call last):
  File "MCMC.py", line 63, in <module>
    sampler = emcee.EnsembleSampler(nwalkers, ndim, log_probability, args=(ells, freqs, data), store=True, backend=backend)
TypeError: __init__() got an unexpected keyword argument 'store'
srun: error: comp18: tasks 0,2,5,7: Exited with exit code 1
---------------
Job output ends
=========================================================
PBS job: finished date = Wed Sep 4 10:33:25 BST 2019
Total run time : 0 Hours 1 Minutes 32 Seconds
=========================================================
